"""
Тесты для исправленных fallback-реализаций
"""
import pytest
import asyncio
import logging
from unittest.mock import patch, MagicMock


class TestFallbackFixes:
    """Тесты исправленных fallback-реализаций"""
    
    def test_sanitize_user_id_fallback(self):
        """Тест fallback sanitize_user_id с некорректными данными"""
        # Имитируем fallback-реализацию
        def sanitize_user_id_fallback(user_id):
            if user_id is None:
                return 0
            try:
                return int(user_id)
            except (ValueError, TypeError):
                return 0
        
        # Тестируем различные входные данные
        assert sanitize_user_id_fallback(123) == 123
        assert sanitize_user_id_fallback("456") == 456
        assert sanitize_user_id_fallback(None) == 0
        assert sanitize_user_id_fallback("abc") == 0
        assert sanitize_user_id_fallback("") == 0
        assert sanitize_user_id_fallback([]) == 0
        assert sanitize_user_id_fallback({}) == 0
    
    @pytest.mark.asyncio
    async def test_circuit_breaker_fallback(self):
        """Тест fallback CircuitBreaker с разными типами функций"""
        # Имитируем fallback-реализацию
        class CircuitBreakerFallback:
            async def call(self, func, *args, **kwargs):
                if not hasattr(func, '__call__'):
                    return func
                
                try:
                    # Проверяем, является ли функция корутиной
                    if asyncio.iscoroutinefunction(func):
                        return await func(*args, **kwargs)
                    else:
                        # Если это обычная функция, вызываем синхронно
                        return func(*args, **kwargs)
                except Exception as e:
                    logging.warning(f"Circuit breaker fallback error: {e}")
                    raise
        
        breaker = CircuitBreakerFallback()
        
        # Асинхронная функция
        async def async_func():
            return 'async_result'
        
        # Синхронная функция
        def sync_func():
            return 'sync_result'
        
        # Тест с асинхронной функцией
        result1 = await breaker.call(async_func)
        assert result1 == 'async_result'
        
        # Тест с синхронной функцией
        result2 = await breaker.call(sync_func)
        assert result2 == 'sync_result'
        
        # Тест с некорректными данными
        result3 = await breaker.call("not_a_function")
        assert result3 == "not_a_function"
    
    @pytest.mark.asyncio
    async def test_rate_limiter_fallback(self):
        """Тест fallback RateLimiter"""
        # Имитируем fallback-реализацию
        class RateLimiterFallback:
            async def is_allowed(self, *args, **kwargs):
                try:
                    return True, None
                except Exception as e:
                    logging.warning(f"Rate limiter fallback error: {e}")
                    return True, None
        
        async def check_rate_limit_fallback(limiter, *args, **kwargs):
            try:
                if limiter and hasattr(limiter, 'is_allowed'):
                    return await limiter.is_allowed(*args, **kwargs)
                return True, None
            except Exception as e:
                logging.warning(f"Rate limit check fallback error: {e}")
                return True, None
        
        limiter = RateLimiterFallback()
        allowed, error = await check_rate_limit_fallback(limiter, 'test_user')
        assert allowed is True
        assert error is None
    
    def test_input_sanitizer_fallback(self):
        """Тест fallback InputSanitizer"""
        # Имитируем fallback-реализацию
        class InputSanitizerFallback:
            @staticmethod
            def sanitize_user_input(data):
                try:
                    return str(data) if data is not None else ""
                except Exception as e:
                    logging.warning(f"Input sanitizer fallback error: {e}")
                    return ""
            
            @staticmethod
            def sanitize_username(username):
                try:
                    return str(username) if username is not None else ""
                except Exception as e:
                    logging.warning(f"Username sanitizer fallback error: {e}")
                    return ""
            
            @staticmethod
            def sanitize_user_id(user_id):
                if user_id is None:
                    return 0
                try:
                    return int(user_id)
                except (ValueError, TypeError) as e:
                    logging.warning(f"User ID sanitizer fallback error: {e}")
                    return 0
        
        sanitizer = InputSanitizerFallback()
        
        # Тест sanitize_user_input
        assert sanitizer.sanitize_user_input("test") == "test"
        assert sanitizer.sanitize_user_input(None) == ""
        assert sanitizer.sanitize_user_input(123) == "123"
        
        # Тест sanitize_username
        assert sanitizer.sanitize_username("user123") == "user123"
        assert sanitizer.sanitize_username(None) == ""
        
        # Тест sanitize_user_id
        assert sanitizer.sanitize_user_id(123) == 123
        assert sanitizer.sanitize_user_id("456") == 456
        assert sanitizer.sanitize_user_id(None) == 0
        assert sanitizer.sanitize_user_id("abc") == 0
    
    def test_output_validator_fallback(self):
        """Тест fallback OutputValidator"""
        # Имитируем fallback-реализацию
        class ValidationResult:
            def __init__(self, is_valid=True, sanitized_data=None, errors=None, warnings=None):
                self.is_valid = is_valid
                self.sanitized_data = sanitized_data or ""
                self.errors = errors or []
                self.warnings = warnings or []
        
        class OutputValidatorFallback:
            @staticmethod
            def validate_message_text(text):
                try:
                    return ValidationResult(True, str(text) if text else "")
                except Exception as e:
                    logging.warning(f"Message text validation fallback error: {e}")
                    return ValidationResult(True, str(text) if text else "")
            
            @staticmethod
            def validate_user_data(data):
                try:
                    return ValidationResult(True, data if data else {})
                except Exception as e:
                    logging.warning(f"User data validation fallback error: {e}")
                    return ValidationResult(True, data if data else {})
        
        validator = OutputValidatorFallback()
        
        # Тест validate_message_text
        result1 = validator.validate_message_text("Hello")
        assert result1.is_valid is True
        assert result1.sanitized_data == "Hello"
        
        result2 = validator.validate_message_text(None)
        assert result2.is_valid is True
        assert result2.sanitized_data == ""
        
        # Тест validate_user_data
        result3 = validator.validate_user_data({"id": 123})
        assert result3.is_valid is True
        assert result3.sanitized_data == {"id": 123}
        
        result4 = validator.validate_user_data(None)
        assert result4.is_valid is True
        assert result4.sanitized_data == {}
    
    @pytest.mark.asyncio
    async def test_resource_manager_fallback(self):
        """Тест fallback ResourceManager"""
        # Имитируем fallback-реализацию
        class ResourceManagerFallback:
            async def register_resource(self, *args, **kwargs):
                try:
                    return True
                except Exception as e:
                    logging.warning(f"Resource registration fallback error: {e}")
                    return True
            
            async def unregister_resource(self, *args, **kwargs):
                try:
                    return True
                except Exception as e:
                    logging.warning(f"Resource unregistration fallback error: {e}")
                    return True
            
            async def cleanup_all(self):
                try:
                    pass
                except Exception as e:
                    logging.warning(f"Resource cleanup fallback error: {e}")
        
        class MemoryManagerFallback:
            @staticmethod
            async def cleanup_memory():
                try:
                    return {"collected_objects": 0}
                except Exception as e:
                    logging.warning(f"Memory cleanup fallback error: {e}")
                    return {"collected_objects": 0}
        
        resource_manager = ResourceManagerFallback()
        memory_manager = MemoryManagerFallback()
        
        # Тест register_resource
        result1 = await resource_manager.register_resource("test_resource")
        assert result1 is True
        
        # Тест unregister_resource
        result2 = await resource_manager.unregister_resource("test_resource")
        assert result2 is True
        
        # Тест cleanup_all
        await resource_manager.cleanup_all()  # Не должно вызывать исключений
        
        # Тест cleanup_memory
        result3 = await memory_manager.cleanup_memory()
        assert result3 == {"collected_objects": 0}
    
    @pytest.mark.asyncio
    async def test_rollback_manager_fallback(self):
        """Тест fallback RollbackManager"""
        # Имитируем fallback-реализацию
        class RollbackManagerFallback:
            async def create_rollback_operation(self, *args, **kwargs):
                try:
                    return "fallback_rollback_id"
                except Exception as e:
                    logging.warning(f"Rollback creation fallback error: {e}")
                    return "fallback_rollback_id"
            
            async def execute_rollback(self, *args, **kwargs):
                try:
                    return True
                except Exception as e:
                    logging.warning(f"Rollback execution fallback error: {e}")
                    return True
            
            async def delete_rollback_operation(self, *args, **kwargs):
                try:
                    return True
                except Exception as e:
                    logging.warning(f"Rollback deletion fallback error: {e}")
                    return True
        
        async def create_admin_removal_rollback_fallback(*args, **kwargs):
            try:
                return "fallback_rollback_id"
            except Exception as e:
                logging.warning(f"Admin removal rollback creation fallback error: {e}")
                return "fallback_rollback_id"
        
        rollback_manager = RollbackManagerFallback()
        
        # Тест create_rollback_operation
        result1 = await rollback_manager.create_rollback_operation("test_operation")
        assert result1 == "fallback_rollback_id"
        
        # Тест execute_rollback
        result2 = await rollback_manager.execute_rollback("test_rollback_id")
        assert result2 is True
        
        # Тест delete_rollback_operation
        result3 = await rollback_manager.delete_rollback_operation("test_rollback_id")
        assert result3 is True
        
        # Тест create_admin_removal_rollback
        result4 = await create_admin_removal_rollback_fallback("test_admin")
        assert result4 == "fallback_rollback_id"
    
    @pytest.mark.asyncio
    async def test_health_checks_fallback(self):
        """Тест fallback HealthChecker"""
        # Имитируем fallback-реализацию
        class HealthCheckerFallback:
            async def check_health(self):
                try:
                    return {"status": "healthy", "checks": {}}
                except Exception as e:
                    logging.warning(f"Health check fallback error: {e}")
                    return {"status": "healthy", "checks": {}}
        
        async def check_database_health_fallback(*args, **kwargs):
            try:
                return {"status": "healthy"}
            except Exception as e:
                logging.warning(f"Database health check fallback error: {e}")
                return {"status": "healthy"}
        
        async def check_telegram_api_health_fallback(*args, **kwargs):
            try:
                return {"status": "healthy"}
            except Exception as e:
                logging.warning(f"Telegram API health check fallback error: {e}")
                return {"status": "healthy"}
        
        health_checker = HealthCheckerFallback()
        
        # Тест check_health
        result1 = await health_checker.check_health()
        assert result1["status"] == "healthy"
        assert "checks" in result1
        
        # Тест check_database_health
        result2 = await check_database_health_fallback()
        assert result2["status"] == "healthy"
        
        # Тест check_telegram_api_health
        result3 = await check_telegram_api_health_fallback()
        assert result3["status"] == "healthy"


if __name__ == "__main__":
    pytest.main([__file__, "-v"])
